<?xml version="1.0" encoding="utf-8"?>

<robot name="basic_link">

    <link name="base_link">
        <visual>
            <origin xyz="0.0 0.0 0.0" rpy="0 0 0"/>
            <geometry>
                <box size="0.2 0.2 0.3"/>
            </geometry>
            <material name="red">
                <color rgba="1 0 0 1"/>
            </material>
        </visual>
        <collision>
            <origin xyz="0.0 0.0 0.0" rpy="0 0 0"/>
            <geometry>
                <box size="0.2 0.2 0.3"/>
            </geometry>
        </collision>
        <inertial>
            <mass value="1"/>
            <origin xyz="0.0 0.0 0.0" rpy="0 0 0"/>
            <inertia ixx="1" ixy="0" ixz="0" iyy="1" iyz="0" izz="1"/>
        </inertial>
    </link>
    <link name="link_1">
        
        <visual>
            <origin xyz="0.0 1.0 0.0" rpy="0 0 0" />
            <geometry>
                <box size="0.1 0.1 0.5" />
            </geometry>
            <material name="green">
                <color rgba="0.0 1.0 0.0 1.0" />
            </material>
        </visual>

        <collision>
            <origin xyz="0.0 1.0 0.0" rpy="0 0 0" />
                <geometry>
                    <box size="0.1 0.1 0.5" />
                </geometry>
        </collision>

        <inertial>
            <origin xyz="0 0 0" rpy="0 0 0" />
            <mass value="1" />
            <inertia ixx="1.0" ixy="0.0" ixz="0.0"
                iyy="1.0" iyz="0.0" izz="1.0" />
        </inertial>

    </link>

    <joint name="base_link_to_link_1_joint" type="revolute">
        <parent link="base_link"/>
        <child link="link_1"/>
        <axis xyz="1 0 0"/>
        <limit lower="-1.57" upper="1.57" velocity="1.0"
            effort="1000.0"/>
        <origin xyz="0 0 0.15" rpy="0 0 0"/>
    </joint>

</robot>








